Workbook

Sheet README
A1: ERP vehicle project costing — dated cost lines
A3: CONTROLS — edit the yellow cells; every sheet follows
A4: As-of date | B4: 46234 | C4: drives the 'Active' flag on CostLines and the 'Active' column on ByVehicle
A5: Calendar year | B5: 2026 | C5: drives the 'In calendar year' flag on CostLines
A6: Financial year | B6: 2026-27 | C6: drives every FY column on ByVehicle. Financial years present: 2024-25, 2025-26, 2026-27
A9: Source | B9: POST http://172.16.10.169:8089/api/general/VehicleEmpMapProjectDetails (body {}, Content-Type: application/json)
A10: Pulled | B10: 1,054 rows, all Project_Type = VEHICLE
A11: Vehicles | B11: 64 distinct
A12: Cost heads | B12: 7 Proj_Activity_Name values / 33 Description values
A13: Period covered | B13: 01-04-2024 to 31-03-2027 (2024-25, 2025-26, 2026-27)
A14: Total Pur_Amount | B14: Rs 28,831,202 across all years
A16: WHY THIS FEED
A17: It is dated | B17: The employee feed's cost lines carry no date, so no payment could be assigned to a year — the open question at the end of 'ERP vehicle costing.xlsx'. Here every line has From_Date/To_Date and a Period_Name, so a cost can be placed in a financial year and pro-rated to a day.
A19: HOW THE ERP MODELS IT
A20: Proj_Activity_Name | B20: The cost head: ADBLU, FC WORK, ROAD TAX, RTO EXPENSE, TYRE, VEHICLE INSURANCE, VEHICLE OUTSIDE SERVICES
A21: Description | B21: A finer split of the same line — VEHICLE OUTSIDE SERVICES breaks into MAINTENANCE SERVICE, MAINTENANCE SERVICE - 2/3, GLASS STICKERS and so on. Equal to Proj_Activity_Name on 806 of 1,054 rows.
A22: Period_Name | B22: YEARLY, QUARTER - I..IV, or a month name. The amount covers THAT period only, so lines are not comparable until they are put on the same footing — use the Days column to pro-rate.
A23: Rate is a UNIT rate | B23: Rate is the rate per unit and Pur_Amount is rate x quantity — they are equal only where the quantity is 1. Pur_Amount is the amount to sum; Rate never is. On the 135 rows where they differ, ADBLU is Rs 60-61 per litre and TYRE is a per-tyre rate. Summing Rate instead of Pur_Amount would understate AdBlue alone by about 40x.
A24: Quantity is derived | B24: The feed has no quantity field, so CostLines derives it as Pur_Amount / Rate. It comes out a whole number on 1,028 of the 1,029 priced rows — 45 litres, 6 tyres — which is what confirms the reading. The exception is TN57AC3636 RTO EXPENSE at 1.87x (Rs 7,500 rate, Rs 14,000 purchased); that one row is either a part-charge or an error, and is worth asking about.
A25: Approved_Date | B25: Blank on 25 rows, and those are exactly the rows where Pur_Amount is 0 (Rs 1,287,922 of rates planned, none of it purchased). Approval is what turns a planned line into spend. Every FY2026-27 line is approved.
A26: Grs_Amount | B26: Identical to Pur_Amount on all rows in this pull, so it is not carried into CostLines.
A27: Employee / Testing | B27: Constant across the feed (VIVEK B / 'T') — the record's owner and a status flag, not per-vehicle data. Kept on CostLines verbatim but carries no information here.
A29: WHAT IT DOES NOT CARRY
A30: No diesel, no salary | B30: The cost heads are tax, insurance, tyres, servicing, RTO and FC work only. Fuel and driver salary — the two largest running costs — are in neither this feed nor the employee feed, so a per-bus running cost cannot be built from the ERP alone yet.
A31: Rented buses have none | B31: 39 of the 77 vehicles in the live fleet have no line here, and they are exactly the RENT VEHICLE entries. Every COMPANY VEHICLE is covered. See the FleetCoverage sheet — the hire charge for a rented bus is invoiced, not planned, so it lives somewhere else in the ERP.
A32: ADBLU stops in 2024 | B32: 123 AdBlue lines exist and every one starts in FY2024-25. Either the head was retired or later AdBlue is being booked elsewhere; worth asking before treating a 2026 total as complete.
A34: READ WITH CARE
A35: Repeated lines are real | B35: 174 rows repeat an existing (vehicle, head, period, from-date, amount) combination. Unlike the employee feed these are not a join artefact — a bus can genuinely take two tyre purchases in one period — but a duplicated entry would look identical, so large repeats deserve a check.
A36: Not a full-year view | B36: A period that has not started yet has no row. FY totals for the current year grow as the year is planned out, so they are not comparable with a closed year until it closes.

Sheet CostLines
A1: Veh_Name | B1: Division | C1: Proj_Activity_Name | D1: Description | E1: Period_Name | F1: From_Date | G1: To_Date | H1: Days | I1: FY | J1: Rate (per unit) | K1: Qty (derived) | L1: Pur_Amount (actual) | M1: Per day | N1: Approved_Date | O1: Approved | P1: Active on as-of | Q1: In cal. year | R1: Order_No | S1: Order_Date | T1: Plan_Entry_No | U1: Project_Type | V1: Testing | W1: Employee
A2: TN57AC3636 | B2: SOCKS | C2: FC WORK | D2: FC WORK | E2: YEARLY | F2: 45383 | G2: 45747 | H2: =IF(OR($F2="",$G2=""),"",$G2-$F2+1) | I2: =IF($F2="","",IF(MONTH($F2)>=4,YEAR($F2)&"-"&TEXT(YEAR($F2)+1-2000,"00"),YEAR($F2)-1&"-"&TEXT(YEAR($F2)-2000,"00"))) | J2: 56950 | K2: =IFERROR($L2/$J2,"") | L2: 56950 | M2: =IFERROR($L2/$H2,"") | N2: 45653 | O2: =IF($N2="","No","Yes") | P2: =IF(OR($F2="",$G2=""),0,IF(AND($F2<=README!$B$4,README!$B$4<=$G2),1,0)) | Q2: =IF(OR($F2="",$G2=""),0,IF(AND($F2<=DATE(README!$B$5,12,31),$G2>=DATE(README!$B$5,1,1)),1,0)) | R2: GUP-VEH0009 | S2: 45475 | T2: 546 | U2: VEHICLE | V2: T | W2: VIVEK B
A3: TN57AC3636 | B3: SOCKS | C3: ROAD TAX | D3: ROAD TAX | E3: YEARLY | F3: 45383 | G3: 45747 | H3: =IF(OR($F3="",$G3=""),"",$G3-$F3+1) | I3: =IF($F3="","",IF(MONTH($F3)>=4,YEAR($F3)&"-"&TEXT(YEAR($F3)+1-2000,"00"),YEAR($F3)-1&"-"&TEXT(YEAR($F3)-2000,"00"))) | J3: 24846 | K3: =IFERROR($L3/$J3,"") | L3: 24846 | M3: =IFERROR($L3/$H3,"") | N3: 45569 | O3: =IF($N3="","No","Yes") | P3: =IF(OR($F3="",$G3=""),0,IF(AND($F3<=README!$B$4,README!$B$4<=$G3),1,0)) | Q3: =IF(OR($F3="",$G3=""),0,IF(AND($F3<=DATE(README!$B$5,12,31),$G3>=DATE(README!$B$5,1,1)),1,0)) | R3: GUP-VEH0011 | S3: 45477 | T3: 548 | U3: VEHICLE | V3: T | W3: VIVEK B
A4: TN57AC3636 | B4: SOCKS | C4: ROAD TAX | D4: ROAD TAX | E4: YEARLY | F4: 45383 | G4: 45747 | H4: =IF(OR($F4="",$G4=""),"",$G4-$F4+1) | I4: =IF($F4="","",IF(MONTH($F4)>=4,YEAR($F4)&"-"&TEXT(YEAR($F4)+1-2000,"00"),YEAR($F4)-1&"-"&TEXT(YEAR($F4)-2000,"00"))) | J4: 24846 | K4: =IFERROR($L4/$J4,"") | L4: 24846 | M4: =IFERROR($L4/$H4,"") | N4: 45649 | O4: =IF($N4="","No","Yes") | P4: =IF(OR($F4="",$G4=""),0,IF(AND($F4<=README!$B$4,README!$B$4<=$G4),1,0)) | Q4: =IF(OR($F4="",$G4=""),0,IF(AND($F4<=DATE(README!$B$5,12,31),$G4>=DATE(README!$B$5,1,1)),1,0)) | R4: GUP-VEH0011 | S4: 45477 | T4: 548 | U4: VEHICLE | V4: T | W4: VIVEK B
A5: TN57AC3636 | B5: SOCKS | C5: ROAD TAX | D5: GREEN TAX | E5: YEARLY | F5: 45383 | G5: 45747 | H5: =IF(OR($F5="",$G5=""),"",$G5-$F5+1) | I5: =IF($F5="","",IF(MONTH($F5)>=4,YEAR($F5)&"-"&TEXT(YEAR($F5)+1-2000,"00"),YEAR($F5)-1&"-"&TEXT(YEAR($F5)-2000,"00"))) | J5: 190 | K5: =IFERROR($L5/$J5,"") | L5: 190 | M5: =IFERROR($L5/$H5,"") | N5: 45649 | O5: =IF($N5="","No","Yes") | P5: =IF(OR($F5="",$G5=""),0,IF(AND($F5<=README!$B$4,README!$B$4<=$G5),1,0)) | Q5: =IF(OR($F5="",$G5=""),0,IF(AND($F5<=DATE(README!$B$5,12,31),$G5>=DATE(README!$B$5,1,1)),1,0)) | R5: GUP-VEH0011 | S5: 45477 | T5: 548 | U5: VEHICLE | V5: T | W5: VIVEK B
A6: TN57AC3636 | B6: SOCKS | C6: ROAD TAX | D6: GREEN TAX | E6: YEARLY | F6: 45383 | G6: 45747 | H6: =IF(OR($F6="",$G6=""),"",$G6-$F6+1) | I6: =IF($F6="","",IF(MONTH($F6)>=4,YEAR($F6)&"-"&TEXT(YEAR($F6)+1-2000,"00"),YEAR($F6)-1&"-"&TEXT(YEAR($F6)-2000,"00"))) | J6: 190 | K6: =IFERROR($L6/$J6,"") | L6: 190 | M6: =IFERROR($L6/$H6,"") | N6: 45569 | O6: =IF($N6="","No","Yes") | P6: =IF(OR($F6="",$G6=""),0,IF(AND($F6<=README!$B$4,README!$B$4<=$G6),1,0)) | Q6: =IF(OR($F6="",$G6=""),0,IF(AND($F6<=DATE(README!$B$5,12,31),$G6>=DATE(README!$B$5,1,1)),1,0)) | R6: GUP-VEH0011 | S6: 45477 | T6: 548 | U6: VEHICLE | V6: T | W6: VIVEK B
A7: TN57AC3636 | B7: SOCKS | C7: ROAD TAX | D7: GREEN TAX | E7: YEARLY | F7: 45383 | G7: 45747 | H7: =IF(OR($F7="",$G7=""),"",$G7-$F7+1) | I7: =IF($F7="","",IF(MONTH($F7)>=4,YEAR($F7)&"-"&TEXT(YEAR($F7)+1-2000,"00"),YEAR($F7)-1&"-"&TEXT(YEAR($F7)-2000,"00"))) | J7: 190 | K7: =IFERROR($L7/$J7,"") | L7: 190 | M7: =IFERROR($L7/$H7,"") | N7: 45481 | O7: =IF($N7="","No","Yes") | P7: =IF(OR($F7="",$G7=""),0,IF(AND($F7<=README!$B$4,README!$B$4<=$G7),1,0)) | Q7: =IF(OR($F7="",$G7=""),0,IF(AND($F7<=DATE(README!$B$5,12,31),$G7>=DATE(README!$B$5,1,1)),1,0)) | R7: GUP-VEH0011 | S7: 45477 | T7: 548 | U7: VEHICLE | V7: T | W7: VIVEK B
A8: TN57AC3636 | B8: SOCKS | C8: ROAD TAX | D8: ROAD TAX | E8: YEARLY | F8: 45383 | G8: 45747 | H8: =IF(OR($F8="",$G8=""),"",$G8-$F8+1) | I8: =IF($F8="","",IF(MONTH($F8)>=4,YEAR($F8)&"-"&TEXT(YEAR($F8)+1-2000,"00"),YEAR($F8)-1&"-"&TEXT(YEAR($F8)-2000,"00"))) | J8: 24846 | K8: =IFERROR($L8/$J8,"") | L8: 24846 | M8: =IFERROR($L8/$H8,"") | N8: 45481 | O8: =IF($N8="","No","Yes") | P8: =IF(OR($F8="",$G8=""),0,IF(AND($F8<=README!$B$4,README!$B$4<=$G8),1,0)) | Q8: =IF(OR($F8="",$G8=""),0,IF(AND($F8<=DATE(README!$B$5,12,31),$G8>=DATE(README!$B$5,1,1)),1,0)) | R8: GUP-VEH0011 | S8: 45477 | T8: 548 | U8: VEHICLE | V8: T | W8: VIVEK B
A9: TN57AC3636 | B9: SOCKS | C9: RTO EXPENSE | D9: RTO EXPENSE | E9: YEARLY | F9: 45383 | G9: 45747 | H9: =IF(OR($F9="",$G9=""),"",$G9-$F9+1) | I9: =IF($F9="","",IF(MONTH($F9)>=4,YEAR($F9)&"-"&TEXT(YEAR($F9)+1-2000,"00"),YEAR($F9)-1&"-"&TEXT(YEAR($F9)-2000,"00"))) | J9: 7500 | K9: =IFERROR($L9/$J9,"") | L9: 7500 | M9: =IFERROR($L9/$H9,"") | N9: 45638 | O9: =IF($N9="","No","Yes") | P9: =IF(OR($F9="",$G9=""),0,IF(AND($F9<=README!$B$4,README!$B$4<=$G9),1,0)) | Q9: =IF(OR($F9="",$G9=""),0,IF(AND($F9<=DATE(README!$B$5,12,31),$G9>=DATE(README!$B$5,1,1)),1,0)) | R9: GUP-VEH0010 | S9: 45475 | T9: 547 | U9: VEHICLE | V9: T | W9: VIVEK B
A10: TN57AC3636 | B10: SOCKS | C10: TYRE | D10: TYRE | E10: YEARLY | F10: 45383 | G10: 45747 | H10: =IF(OR($F10="",$G10=""),"",$G10-$F10+1) | I10: =IF($F10="","",IF(MONTH($F10)>=4,YEAR($F10)&"-"&TEXT(YEAR($F10)+1-2000,"00"),YEAR($F10)-1&"-"&TEXT(YEAR($F10)-2000,"00"))) | J10: 19200 | K10: =IFERROR($L10/$J10,"") | L10: 19200 | M10: =IFERROR($L10/$H10,"") | N10: 45443 | O10: =IF($N10="","No","Yes") | P10: =IF(OR($F10="",$G10=""),0,IF(AND($F10<=README!$B$4,README!$B$4<=$G10),1,0)) | Q10: =IF(OR($F10="",$G10=""),0,IF(AND($F10<=DATE(README!$B$5,12,31),$G10>=DATE(README!$B$5,1,1)),1,0)) | R10: GUP-VEH0006 | S10: 45442 | T10: 522 | U10: VEHICLE | V10: T | W10: VIVEK B
A11: TN57AC3636 | B11: SOCKS | C11: VEHICLE INSURANCE | D11: VEHICLE INSURANCE | E11: YEARLY | F11: 45383 | G11: 45747 | H11: =IF(OR($F11="",$G11=""),"",$G11-$F11+1) | I11: =IF($F11="","",IF(MONTH($F11)>=4,YEAR($F11)&"-"&TEXT(YEAR($F11)+1-2000,"00"),YEAR($F11)-1&"-"&TEXT(YEAR($F11)-2000,"00"))) | J11: 59316 | K11: =IFERROR($L11/$J11,"") | L11: 59316 | M11: =IFERROR($L11/$H11,"") | N11: 45632 | O11: =IF($N11="","No","Yes") | P11: =IF(OR($F11="",$G11=""),0,IF(AND($F11<=README!$B$4,README!$B$4<=$G11),1,0)) | Q11: =IF(OR($F11="",$G11=""),0,IF(AND($F11<=DATE(README!$B$5,12,31),$G11>=DATE(README!$B$5,1,1)),1,0)) | R11: GUP-VEH0013 | S11: 45478 | T11: 550 | U11: VEHICLE | V11: T | W11: VIVEK B
A12: TN57AC3636 | B12: SOCKS | C12: FC WORK | D12: FC WORK | E12: YEARLY | F12: 45748 | G12: 46112 | H12: =IF(OR($F12="",$G12=""),"",$G12-$F12+1) | I12: =IF($F12="","",IF(MONTH($F12)>=4,YEAR($F12)&"-"&TEXT(YEAR($F12)+1-2000,"00"),YEAR($F12)-1&"-"&TEXT(YEAR($F12)-2000,"00"))) | J12: 40020 | K12: =IFERROR($L12/$J12,"") | L12: 40020 | M12: =IFERROR($L12/$H12,"") | N12: 46028 | O12: =IF($N12="","No","Yes") | P12: =IF(OR($F12="",$G12=""),0,IF(AND($F12<=README!$B$4,README!$B$4<=$G12),1,0)) | Q12: =IF(OR($F12="",$G12=""),0,IF(AND($F12<=DATE(README!$B$5,12,31),$G12>=DATE(README!$B$5,1,1)),1,0)) | R12: GUP-VEH0021 | S12: 45832 | T12: 654 | U12: VEHICLE | V12: T | W12: VIVEK B
A13: TN57AC3636 | B13: SOCKS | C13: ROAD TAX | D13: GREEN TAX | E13: QUARTER - I | F13: 45748 | G13: 45838 | H13: =IF(OR($F13="",$G13=""),"",$G13-$F13+1) | I13: =IF($F13="","",IF(MONTH($F13)>=4,YEAR($F13)&"-"&TEXT(YEAR($F13)+1-2000,"00"),YEAR($F13)-1&"-"&TEXT(YEAR($F13)-2000,"00"))) | J13: 190 | K13: =IFERROR($L13/$J13,"") | L13: 190 | M13: =IFERROR($L13/$H13,"") | N13: 46030 | O13: =IF($N13="","No","Yes") | P13: =IF(OR($F13="",$G13=""),0,IF(AND($F13<=README!$B$4,README!$B$4<=$G13),1,0)) | Q13: =IF(OR($F13="",$G13=""),0,IF(AND($F13<=DATE(README!$B$5,12,31),$G13>=DATE(README!$B$5,1,1)),1,0)) | R13: GUP-VEH0014 | S13: 45748 | T13: 609 | U13: VEHICLE | V13: T | W13: VIVEK B
... A61: TN57AF3636 | B61: SOCKS | C61: ROAD TAX | D61: ROAD TAX | E61: YEARLY | F61: 45383 | G61: 45747 | H61: =IF(OR($F61="",$G61=""),"",$G61-$F61+1) | I61: =IF($F61="","",IF(MONTH($F61)>=4,YEAR($F61)&"-"&TEXT(YEAR($F61)+1-2000,"00"),YEAR($F61)-1&"-"&TEXT(YEAR($F61)-2000,"00"))) | J61: 24846 | K61: =IFERROR($L61/$J61,"") | L61: 24846 | M61: =IFERROR($L61/$H61,"") | N61: 45481 | O61: =IF($N61="","No","Yes") | P61: =IF(OR($F61="",$G61=""),0,IF(AND($F61<=README!$B$4,README!$B$4<=$G61),1,0)) | Q61: =IF(OR($F61="",$G61=""),0,IF(AND($F61<=DATE(README!$B$5,12,31),$G61>=DATE(README!$B$5,1,1)),1,0)) | R61: GUP-VEH0011 | S61: 45477 | T61: 548 | U61: VEHICLE | V61: T | W61: VIVEK B
A62: TN57AF3636 | B62: SOCKS | C62: TYRE | D62: TYRE | E62: YEARLY | F62: 45383 | G62: 45747 | H62: =IF(OR($F62="",$G62=""),"",$G62-$F62+1) | I62: =IF($F62="","",IF(MONTH($F62)>=4,YEAR($F62)&"-"&TEXT(YEAR($F62)+1-2000,"00"),YEAR($F62)-1&"-"&TEXT(YEAR($F62)-2000,"00"))) | J62: 19200 | K62: =IFERROR($L62/$J62,"") | L62: 0 | M62: =IFERROR($L62/$H62,"") | O62: =IF($N62="","No","Yes") | P62: =IF(OR($F62="",$G62=""),0,IF(AND($F62<=README!$B$4,README!$B$4<=$G62),1,0)) | Q62: =IF(OR($F62="",$G62=""),0,IF(AND($F62<=DATE(README!$B$5,12,31),$G62>=DATE(README!$B$5,1,1)),1,0)) | R62: GUP-VEH0006 | S62: 45442 | T62: 522 | U62: VEHICLE | V62: T | W62: VIVEK B
A63: TN57AF3636 | B63: SOCKS | C63: VEHICLE INSURANCE | D63: VEHICLE INSURANCE | E63: YEARLY | F63: 45383 | G63: 45747 | H63: =IF(OR($F63="",$G63=""),"",$G63-$F63+1) | I63: =IF($F63="","",IF(MONTH($F63)>=4,YEAR($F63)&"-"&TEXT(YEAR($F63)+1-2000,"00"),YEAR($F63)-1&"-"&TEXT(YEAR($F63)-2000,"00"))) | J63: 59895 | K63: =IFERROR($L63/$J63,"") | L63: 59895 | M63: =IFERROR($L63/$H63,"") | N63: 45632 | O63: =IF($N63="","No","Yes") | P63: =IF(OR($F63="",$G63=""),0,IF(AND($F63<=README!$B$4,README!$B$4<=$G63),1,0)) | Q63: =IF(OR($F63="",$G63=""),0,IF(AND($F63<=DATE(README!$B$5,12,31),$G63>=DATE(README!$B$5,1,1)),1,0)) | R63: GUP-VEH0013 | S63: 45478 | T63: 550 | U63: VEHICLE | V63: T | W63: VIVEK B
A64: TN57AF3636 | B64: SOCKS | C64: FC WORK | D64: FC WORK | E64: YEARLY | F64: 45748 | G64: 46112 | H64: =IF(OR($F64="",$G64=""),"",$G64-$F64+1) | I64: =IF($F64="","",IF(MONTH($F64)>=4,YEAR($F64)&"-"&TEXT(YEAR($F64)+1-2000,"00"),YEAR($F64)-1&"-"&TEXT(YEAR($F64)-2000,"00"))) | J64: 91656.71 | K64: =IFERROR($L64/$J64,"") | L64: 91656.71 | M64: =IFERROR($L64/$H64,"") | N64: 45847 | O64: =IF($N64="","No","Yes") | P64: =IF(OR($F64="",$G64=""),0,IF(AND($F64<=README!$B$4,README!$B$4<=$G64),1,0)) | Q64: =IF(OR($F64="",$G64=""),0,IF(AND($F64<=DATE(README!$B$5,12,31),$G64>=DATE(README!$B$5,1,1)),1,0)) | R64: GUP-VEH0021 | S64: 45832 | T64: 654 | U64: VEHICLE | V64: T | W64: VIVEK B
A65: TN57AF3636 | B65: SOCKS | C65: ROAD TAX | D65: GREEN TAX | E65: QUARTER - I | F65: 45748 | G65: 45838 | H65: =IF(OR($F65="",$G65=""),"",$G65-$F65+1) | I65: =IF($F65="","",IF(MONTH($F65)>=4,YEAR($F65)&"-"&TEXT(YEAR($F65)+1-2000,"00"),YEAR($F65)-1&"-"&TEXT(YEAR($F65)-2000,"00"))) | J65: 190 | K65: =IFERROR($L65/$J65,"") | L65: 190 | M65: =IFERROR($L65/$H65,"") | N65: 46030 | O65: =IF($N65="","No","Yes") | P65: =IF(OR($F65="",$G65=""),0,IF(AND($F65<=README!$B$4,README!$B$4<=$G65),1,0)) | Q65: =IF(OR($F65="",$G65=""),0,IF(AND($F65<=DATE(README!$B$5,12,31),$G65>=DATE(README!$B$5,1,1)),1,0)) | R65: GUP-VEH0014 | S65: 45748 | T65: 609 | U65: VEHICLE | V65: T | W65: VIVEK B
A66: TN57AF3636 | B66: SOCKS | C66: ROAD TAX | D66: ROAD TAX | E66: QUARTER - I | F66: 45748 | G66: 45838 | H66: =IF(OR($F66="",$G66=""),"",$G66-$F66+1) | I66: =IF($F66="","",IF(MONTH($F66)>=4,YEAR($F66)&"-"&TEXT(YEAR($F66)+1-2000,"00"),YEAR($F66)-1&"-"&TEXT(YEAR($F66)-2000,"00"))) | J66: 24846 | K66: =IFERROR($L66/$J66,"") | L66: 24846 | M66: =IFERROR($L66/$H66,"") | N66: 46030 | O66: =IF($N66="","No","Yes") | P66: =IF(OR($F66="",$G66=""),0,IF(AND($F66<=README!$B$4,README!$B$4<=$G66),1,0)) | Q66: =IF(OR($F66="",$G66=""),0,IF(AND($F66<=DATE(README!$B$5,12,31),$G66>=DATE(README!$B$5,1,1)),1,0)) | R66: GUP-VEH0014 | S66: 45748 | T66: 609 | U66: VEHICLE | V66: T | W66: VIVEK B
A67: TN57AF3636 | B67: SOCKS | C67: RTO EXPENSE | D67: RTO EXPENSE | E67: YEARLY | F67: 45748 | G67: 46112 | H67: =IF(OR($F67="",$G67=""),"",$G67-$F67+1) | I67: =IF($F67="","",IF(MONTH($F67)>=4,YEAR($F67)&"-"&TEXT(YEAR($F67)+1-2000,"00"),YEAR($F67)-1&"-"&TEXT(YEAR($F67)-2000,"00"))) | J67: 7500 | K67: =IFERROR($L67/$J67,"") | L67: 7500 | M67: =IFERROR($L67/$H67,"") | N67: 45834 | O67: =IF($N67="","No","Yes") | P67: =IF(OR($F67="",$G67=""),0,IF(AND($F67<=README!$B$4,README!$B$4<=$G67),1,0)) | Q67: =IF(OR($F67="",$G67=""),0,IF(AND($F67<=DATE(README!$B$5,12,31),$G67>=DATE(README!$B$5,1,1)),1,0)) | R67: GUP-VEH0022 | S67: 45834 | T67: 655 | U67: VEHICLE | V67: T | W67: VIVEK B
A68: TN57AF3636 | B68: SOCKS | C68: TYRE | D68: TYRE | E68: YEARLY | F68: 45748 | G68: 46112 | H68: =IF(OR($F68="",$G68=""),"",$G68-$F68+1) | I68: =IF($F68="","",IF(MONTH($F68)>=4,YEAR($F68)&"-"&TEXT(YEAR($F68)+1-2000,"00"),YEAR($F68)-1&"-"&TEXT(YEAR($F68)-2000,"00"))) | J68: 19200 | K68: =IFERROR($L68/$J68,"") | L68: 19200 | M68: =IFERROR($L68/$H68,"") | N68: 45986 | O68: =IF($N68="","No","Yes") | P68: =IF(OR($F68="",$G68=""),0,IF(AND($F68<=README!$B$4,README!$B$4<=$G68),1,0)) | Q68: =IF(OR($F68="",$G68=""),0,IF(AND($F68<=DATE(README!$B$5,12,31),$G68>=DATE(README!$B$5,1,1)),1,0)) | R68: GUP-VEH0025 | S68: 45957 | T68: 726 | U68: VEHICLE | V68: T | W68: VIVEK B
A69: TN57AF3636 | B69: SOCKS | C69: VEHICLE INSURANCE | D69: VEHICLE INSURANCE | E69: YEARLY | F69: 45748 | G69: 46112 | H69: =IF(OR($F69="",$G69=""),"",$G69-$F69+1) | I69: =IF($F69="","",IF(MONTH($F69)>=4,YEAR($F69)&"-"&TEXT(YEAR($F69)+1-2000,"00"),YEAR($F69)-1&"-"&TEXT(YEAR($F69)-2000,"00"))) | J69: 59627 | K69: =IFERROR($L69/$J69,"") | L69: 59627 | M69: =IFERROR($L69/$H69,"") | N69: 45994 | O69: =IF($N69="","No","Yes") | P69: =IF(OR($F69="",$G69=""),0,IF(AND($F69<=README!$B$4,README!$B$4<=$G69),1,0)) | Q69: =IF(OR($F69="",$G69=""),0,IF(AND($F69<=DATE(README!$B$5,12,31),$G69>=DATE(README!$B$5,1,1)),1,0)) | R69: GUP-VEH0020 | S69: 45799 | T69: 645 | U69: VEHICLE | V69: T | W69: VIVEK B
A70: TN57AF3636 | B70: SOCKS | C70: ROAD TAX | D70: ROAD TAX | E70: QUARTER - II | F70: 45839 | G70: 45930 | H70: =IF(OR($F70="",$G70=""),"",$G70-$F70+1) | I70: =IF($F70="","",IF(MONTH($F70)>=4,YEAR($F70)&"-"&TEXT(YEAR($F70)+1-2000,"00"),YEAR($F70)-1&"-"&TEXT(YEAR($F70)-2000,"00"))) | J70: 24846 | K70: =IFERROR($L70/$J70,"") | L70: 24846 | M70: =IFERROR($L70/$H70,"") | N70: 46030 | O70: =IF($N70="","No","Yes") | P70: =IF(OR($F70="",$G70=""),0,IF(AND($F70<=README!$B$4,README!$B$4<=$G70),1,0)) | Q70: =IF(OR($F70="",$G70=""),0,IF(AND($F70<=DATE(README!$B$5,12,31),$G70>=DATE(README!$B$5,1,1)),1,0)) | R70: GUP-VEH0014 | S70: 45748 | T70: 609 | U70: VEHICLE | V70: T | W70: VIVEK B
A71: TN57AF3636 | B71: SOCKS | C71: ROAD TAX | D71: ROAD TAX | E71: QUARTER - III | F71: 45931 | G71: 46022 | H71: =IF(OR($F71="",$G71=""),"",$G71-$F71+1) | I71: =IF($F71="","",IF(MONTH($F71)>=4,YEAR($F71)&"-"&TEXT(YEAR($F71)+1-2000,"00"),YEAR($F71)-1&"-"&TEXT(YEAR($F71)-2000,"00"))) | J71: 24856 | K71: =IFERROR($L71/$J71,"") | L71: 24856 | M71: =IFERROR($L71/$H71,"") | N71: 46030 | O71: =IF($N71="","No","Yes") | P71: =IF(OR($F71="",$G71=""),0,IF(AND($F71<=README!$B$4,README!$B$4<=$G71),1,0)) | Q71: =IF(OR($F71="",$G71=""),0,IF(AND($F71<=DATE(README!$B$5,12,31),$G71>=DATE(README!$B$5,1,1)),1,0)) | R71: GUP-VEH0014 | S71: 45748 | T71: 609 | U71: VEHICLE | V71: T | W71: VIVEK B
A72: TN57AF3636 | B72: SOCKS | C72: ROAD TAX | D72: ROAD TAX | E72: QUARTER - IV | F72: 46023 | G72: 46112 | H72: =IF(OR($F72="",$G72=""),"",$G72-$F72+1) | I72: =IF($F72="","",IF(MONTH($F72)>=4,YEAR($F72)&"-"&TEXT(YEAR($F72)+1-2000,"00"),YEAR($F72)-1&"-"&TEXT(YEAR($F72)-2000,"00"))) | J72: 24846 | K72: =IFERROR($L72/$J72,"") | L72: 24846 | M72: =IFERROR($L72/$H72,"") | N72: 46030 | O72: =IF($N72="","No","Yes") | P72: =IF(OR($F72="",$G72=""),0,IF(AND($F72<=README!$B$4,README!$B$4<=$G72),1,0)) | Q72: =IF(OR($F72="",$G72=""),0,IF(AND($F72<=DATE(README!$B$5,12,31),$G72>=DATE(README!$B$5,1,1)),1,0)) | R72: GUP-VEH0014 | S72: 45748 | T72: 609 | U72: VEHICLE | V72: T | W72: VIVEK B
A73: TN57AF3636 | B73: SOCKS | C73: ROAD TAX | D73: ROAD TAX | E73: QUARTER - I | F73: 46113 | G73: 46203 | H73: =IF(OR($F73="",$G73=""),"",$G73-$F73+1) | I73: =IF($F73="","",IF(MONTH($F73)>=4,YEAR($F73)&"-"&TEXT(YEAR($F73)+1-2000,"00"),YEAR($F73)-1&"-"&TEXT(YEAR($F73)-2000,"00"))) | J73: 24250 | K73: =IFERROR($L73/$J73,"") | L73: 24250 | M73: =IFERROR($L73/$H73,"") | N73: 46088 | O73: =IF($N73="","No","Yes") | P73: =IF(OR($F73="",$G73=""),0,IF(AND($F73<=README!$B$4,README!$B$4<=$G73),1,0)) | Q73: =IF(OR($F73="",$G73=""),0,IF(AND($F73<=DATE(README!$B$5,12,31),$G73>=DATE(README!$B$5,1,1)),1,0)) | R73: GUP-VEH0030 | S73: 46113 | T73: 796 | U73: VEHICLE | V73: T | W73: VIVEK B
A74: TN57AF3636 | B74: SOCKS | C74: ROAD TAX | D74: ROAD TAX | E74: QUARTER - II | F74: 46204 | G74: 46295 | H74: =IF(OR($F74="",$G74=""),"",$G74-$F74+1) | I74: =IF($F74="","",IF(MONTH($F74)>=4,YEAR($F74)&"-"&TEXT(YEAR($F74)+1-2000,"00"),YEAR($F74)-1&"-"&TEXT(YEAR($F74)-2000,"00"))) | J74: 24250 | K74: =IFERROR($L74/$J74,"") | L74: 24250 | M74: =IFERROR($L74/$H74,"") | N74: 46196 | O74: =IF($N74="","No","Yes") | P74: =IF(OR($F74="",$G74=""),0,IF(AND($F74<=README!$B$4,README!$B$4<=$G74),1,0)) | Q74: =IF(OR($F74="",$G74=""),0,IF(AND($F74<=DATE(README!$B$5,12,31),$G74>=DATE(README!$B$5,1,1)),1,0)) | R74: GUP-VEH0030 | S74: 46113 | T74: 796 | U74: VEHICLE | V74: T | W74: VIVEK B
... A76: TN57AH3636 | B76: SOCKS | C76: RTO EXPENSE | D76: RTO EXPENSE | E76: YEARLY | F76: 45383 | G76: 45747 | H76: =IF(OR($F76="",$G76=""),"",$G76-$F76+1) | I76: =IF($F76="","",IF(MONTH($F76)>=4,YEAR($F76)&"-"&TEXT(YEAR($F76)+1-2000,"00"),YEAR($F76)-1&"-"&TEXT(YEAR($F76)-2000,"00"))) | J76: 7000 | K76: =IFERROR($L76/$J76,"") | L76: 7000 | M76: =IFERROR($L76/$H76,"") | N76: 45481 | O76: =IF($N76="","No","Yes") | P76: =IF(OR($F76="",$G76=""),0,IF(AND($F76<=README!$B$4,README!$B$4<=$G76),1,0)) | Q76: =IF(OR($F76="",$G76=""),0,IF(AND($F76<=DATE(README!$B$5,12,31),$G76>=DATE(README!$B$5,1,1)),1,0)) | R76: GUP-VEH0010 | S76: 45475 | T76: 547 | U76: VEHICLE | V76: T | W76: VIVEK B
A77: TN57AH3636 | B77: SOCKS | C77: TYRE | D77: TYRE | E77: YEARLY | F77: 45383 | G77: 45747 | H77: =IF(OR($F77="",$G77=""),"",$G77-$F77+1) | I77: =IF($F77="","",IF(MONTH($F77)>=4,YEAR($F77)&"-"&TEXT(YEAR($F77)+1-2000,"00"),YEAR($F77)-1&"-"&TEXT(YEAR($F77)-2000,"00"))) | J77: 35300 | K77: =IFERROR($L77/$J77,"") | L77: 0 | M77: =IFERROR($L77/$H77,"") | O77: =IF($N77="","No","Yes") | P77: =IF(OR($F77="",$G77=""),0,IF(AND($F77<=README!$B$4,README!$B$4<=$G77),1,0)) | Q77: =IF(OR($F77="",$G77=""),0,IF(AND($F77<=DATE(README!$B$5,12,31),$G77>=DATE(README!$B$5,1,1)),1,0)) | R77: GUP-VEH0006 | S77: 45442 | T77: 522 | U77: VEHICLE | V77: T | W77: VIVEK B
A78: TN57AH3636 | B78: SOCKS | C78: VEHICLE INSURANCE | D78: VEHICLE INSURANCE | E78: YEARLY | F78: 45383 | G78: 45747 | H78: =IF(OR($F78="",$G78=""),"",$G78-$F78+1) | I78: =IF($F78="","",IF(MONTH($F78)>=4,YEAR($F78)&"-"&TEXT(YEAR($F78)+1-2000,"00"),YEAR($F78)-1&"-"&TEXT(YEAR($F78)-2000,"00"))) | J78: 40888 | K78: =IFERROR($L78/$J78,"") | L78: 40888 | M78: =IFERROR($L78/$H78,"") | N78: 45612 | O78: =IF($N78="","No","Yes") | P78: =IF(OR($F78="",$G78=""),0,IF(AND($F78<=README!$B$4,README!$B$4<=$G78),1,0)) | Q78: =IF(OR($F78="",$G78=""),0,IF(AND($F78<=DATE(README!$B$5,12,31),$G78>=DATE(README!$B$5,1,1)),1,0)) | R78: GUP-VEH0013 | S78: 45478 | T78: 550 | U78: VEHICLE | V78: T | W78: VIVEK B
A79: TN57AH3636 | B79: SOCKS | C79: FC WORK | D79: FC WORK | E79: YEARLY | F79: 45748 | G79: 46112 | H79: =IF(OR($F79="",$G79=""),"",$G79-$F79+1) | I79: =IF($F79="","",IF(MONTH($F79)>=4,YEAR($F79)&"-"&TEXT(YEAR($F79)+1-2000,"00"),YEAR($F79)-1&"-"&TEXT(YEAR($F79)-2000,"00"))) | J79: 67000 | K79: =IFERROR($L79/$J79,"") | L79: 67000 | M79: =IFERROR($L79/$H79,"") | N79: 45854 | O79: =IF($N79="","No","Yes") | P79: =IF(OR($F79="",$G79=""),0,IF(AND($F79<=README!$B$4,README!$B$4<=$G79),1,0)) | Q79: =IF(OR($F79="",$G79=""),0,IF(AND($F79<=DATE(README!$B$5,12,31),$G79>=DATE(README!$B$5,1,1)),1,0)) | R79: GUP-VEH0021 | S79: 45832 | T79: 654 | U79: VEHICLE | V79: T | W79: VIVEK B
A80: TN57AH3636 | B80: SOCKS | C80: ROAD TAX | D80: GREEN TAX | E80: QUARTER - I | F80: 45748 | G80: 45838 | H80: =IF(OR($F80="",$G80=""),"",$G80-$F80+1) | I80: =IF($F80="","",IF(MONTH($F80)>=4,YEAR($F80)&"-"&TEXT(YEAR($F80)+1-2000,"00"),YEAR($F80)-1&"-"&TEXT(YEAR($F80)-2000,"00"))) | J80: 760 | K80: =IFERROR($L80/$J80,"") | L80: 760 | M80: =IFERROR($L80/$H80,"") | N80: 46030 | O80: =IF($N80="","No","Yes") | P80: =IF(OR($F80="",$G80=""),0,IF(AND($F80<=README!$B$4,README!$B$4<=$G80),1,0)) | Q80: =IF(OR($F80="",$G80=""),0,IF(AND($F80<=DATE(README!$B$5,12,31),$G80>=DATE(README!$B$5,1,1)),1,0)) | R80: GUP-VEH0014 | S80: 45748 | T80: 609 | U80: VEHICLE | V80: T | W80: VIVEK B
A81: TN57AH3636 | B81: SOCKS | C81: ROAD TAX | D81: ROAD TAX | E81: QUARTER - I | F81: 45748 | G81: 45838 | H81: =IF(OR($F81="",$G81=""),"",$G81-$F81+1) | I81: =IF($F81="","",IF(MONTH($F81)>=4,YEAR($F81)&"-"&TEXT(YEAR($F81)+1-2000,"00"),YEAR($F81)-1&"-"&TEXT(YEAR($F81)-2000,"00"))) | J81: 17092 | K81: =IFERROR($L81/$J81,"") | L81: 17092 | M81: =IFERROR($L81/$H81,"") | N81: 46030 | O81: =IF($N81="","No","Yes") | P81: =IF(OR($F81="",$G81=""),0,IF(AND($F81<=README!$B$4,README!$B$4<=$G81),1,0)) | Q81: =IF(OR($F81="",$G81=""),0,IF(AND($F81<=DATE(README!$B$5,12,31),$G81>=DATE(README!$B$5,1,1)),1,0)) | R81: GUP-VEH0014 | S81: 45748 | T81: 609 | U81: VEHICLE | V81: T | W81: VIVEK B
A82: TN57AH3636 | B82: SOCKS | C82: RTO EXPENSE | D82: RTO EXPENSE | E82: YEARLY | F82: 45748 | G82: 46112 | H82: =IF(OR($F82="",$G82=""),"",$G82-$F82+1) | I82: =IF($F82="","",IF(MONTH($F82)>=4,YEAR($F82)&"-"&TEXT(YEAR($F82)+1-2000,"00"),YEAR($F82)-1&"-"&TEXT(YEAR($F82)-2000,"00"))) | J82: 6500 | K82: =IFERROR($L82/$J82,"") | L82: 6500 | M82: =IFERROR($L82/$H82,"") | N82: 45854 | O82: =IF($N82="","No","Yes") | P82: =IF(OR($F82="",$G82=""),0,IF(AND($F82<=README!$B$4,README!$B$4<=$G82),1,0)) | Q82: =IF(OR($F82="",$G82=""),0,IF(AND($F82<=DATE(README!$B$5,12,31),$G82>=DATE(README!$B$5,1,1)),1,0)) | R82: GUP-VEH0022 | S82: 45834 | T82: 655 | U82: VEHICLE | V82: T | W82: VIVEK B
A83: TN57AH3636 | B83: SOCKS | C83: TYRE | D83: TYRE | E83: YEARLY | F83: 45748 | G83: 46112 | H83: =IF(OR($F83="",$G83=""),"",$G83-$F83+1) | I83: =IF($F83="","",IF(MONTH($F83)>=4,YEAR($F83)&"-"&TEXT(YEAR($F83)+1-2000,"00"),YEAR($F83)-1&"-"&TEXT(YEAR($F83)-2000,"00"))) | J83: 37500 | K83: =IFERROR($L83/$J83,"") | L83: 37500 | M83: =IFERROR($L83/$H83,"") | N83: 45957 | O83: =IF($N83="","No","Yes") | P83: =IF(OR($F83="",$G83=""),0,IF(AND($F83<=README!$B$4,README!$B$4<=$G83),1,0)) | Q83: =IF(OR($F83="",$G83=""),0,IF(AND($F83<=DATE(README!$B$5,12,31),$G83>=DATE(README!$B$5,1,1)),1,0)) | R83: GUP-VEH0025 | S83: 45957 | T83: 726 | U83: VEHICLE | V83: T | W83: VIVEK B
A84: TN57AH3636 | B84: SOCKS | C84: VEHICLE INSURANCE | D84: VEHICLE INSURANCE | E84: YEARLY | F84: 45748 | G84: 46112 | H84: =IF(OR($F84="",$G84=""),"",$G84-$F84+1) | I84: =IF($F84="","",IF(MONTH($F84)>=4,YEAR($F84)&"-"&TEXT(YEAR($F84)+1-2000,"00"),YEAR($F84)-1&"-"&TEXT(YEAR($F84)-2000,"00"))) | J84: 40270 | K84: =IFERROR($L84/$J84,"") | L84: 40270 | M84: =IFERROR($L84/$H84,"") | N84: 45966 | O84: =IF($N84="","No","Yes") | P84: =IF(OR($F84="",$G84=""),0,IF(AND($F84<=README!$B$4,README!$B$4<=$G84),1,0)) | Q84: =IF(OR($F84="",$G84=""),0,IF(AND($F84<=DATE(README!$B$5,12,31),$G84>=DATE(README!$B$5,1,1)),1,0)) | R84: GUP-VEH0020 | S84: 45799 | T84: 645 | U84: VEHICLE | V84: T | W84: VIVEK B
A85: TN57AH3636 | B85: SOCKS | C85: ROAD TAX | D85: GREEN TAX | E85: QUARTER - II | F85: 45839 | G85: 45930 | H85: =IF(OR($F85="",$G85=""),"",$G85-$F85+1) | I85: =IF($F85="","",IF(MONTH($F85)>=4,YEAR($F85)&"-"&TEXT(YEAR($F85)+1-2000,"00"),YEAR($F85)-1&"-"&TEXT(YEAR($F85)-2000,"00"))) | J85: 190 | K85: =IFERROR($L85/$J85,"") | L85: 190 | M85: =IFERROR($L85/$H85,"") | N85: 46030 | O85: =IF($N85="","No","Yes") | P85: =IF(OR($F85="",$G85=""),0,IF(AND($F85<=README!$B$4,README!$B$4<=$G85),1,0)) | Q85: =IF(OR($F85="",$G85=""),0,IF(AND($F85<=DATE(README!$B$5,12,31),$G85>=DATE(README!$B$5,1,1)),1,0)) | R85: GUP-VEH0014 | S85: 45748 | T85: 609 | U85: VEHICLE | V85: T | W85: VIVEK B
A86: TN57AH3636 | B86: SOCKS | C86: ROAD TAX | D86: ROAD TAX | E86: QUARTER - II | F86: 45839 | G86: 45930 | H86: =IF(OR($F86="",$G86=""),"",$G86-$F86+1) | I86: =IF($F86="","",IF(MONTH($F86)>=4,YEAR($F86)&"-"&TEXT(YEAR($F86)+1-2000,"00"),YEAR($F86)-1&"-"&TEXT(YEAR($F86)-2000,"00"))) | J86: 4545 | K86: =IFERROR($L86/$J86,"") | L86: 4545 | M86: =IFERROR($L86/$H86,"") | N86: 46030 | O86: =IF($N86="","No","Yes") | P86: =IF(OR($F86="",$G86=""),0,IF(AND($F86<=README!$B$4,README!$B$4<=$G86),1,0)) | Q86: =IF(OR($F86="",$G86=""),0,IF(AND($F86<=DATE(README!$B$5,12,31),$G86>=DATE(README!$B$5,1,1)),1,0)) | R86: GUP-VEH0014 | S86: 45748 | T86: 609 | U86: VEHICLE | V86: T | W86: VIVEK B
A87: TN57AH3636 | B87: SOCKS | C87: ROAD TAX | D87: ROAD TAX | E87: QUARTER - III | F87: 45931 | G87: 46022 | H87: =IF(OR($F87="",$G87=""),"",$G87-$F87+1) | I87: =IF($F87="","",IF(MONTH($F87)>=4,YEAR($F87)&"-"&TEXT(YEAR($F87)+1-2000,"00"),YEAR($F87)-1&"-"&TEXT(YEAR($F87)-2000,"00"))) | J87: 4555 | K87: =IFERROR($L87/$J87,"") | L87: 4555 | M87: =IFERROR($L87/$H87,"") | N87: 46030 | O87: =IF($N87="","No","Yes") | P87: =IF(OR($F87="",$G87=""),0,IF(AND($F87<=README!$B$4,README!$B$4<=$G87),1,0)) | Q87: =IF(OR($F87="",$G87=""),0,IF(AND($F87<=DATE(README!$B$5,12,31),$G87>=DATE(README!$B$5,1,1)),1,0)) | R87: GUP-VEH0014 | S87: 45748 | T87: 609 | U87: VEHICLE | V87: T | W87: VIVEK B
A88: TN57AH3636 | B88: GENERAL | C88: VEHICLE OUTSIDE SERVICES | D88: ELETRICAL WORK - VEHICLE | E88: NOVEMBER | F88: 45962 | G88: 45991 | H88: =IF(OR($F88="",$G88=""),"",$G88-$F88+1) | I88: =IF($F88="","",IF(MONTH($F88)>=4,YEAR($F88)&"-"&TEXT(YEAR($F88)+1-2000,"00"),YEAR($F88)-1&"-"&TEXT(YEAR($F88)-2000,"00"))) | J88: 4704 | K88: =IFERROR($L88/$J88,"") | L88: 4704 | M88: =IFERROR($L88/$H88,"") | N88: 45986 | O88: =IF($N88="","No","Yes") | P88: =IF(OR($F88="",$G88=""),0,IF(AND($F88<=README!$B$4,README!$B$4<=$G88),1,0)) | Q88: =IF(OR($F88="",$G88=""),0,IF(AND($F88<=DATE(README!$B$5,12,31),$G88>=DATE(README!$B$5,1,1)),1,0)) | R88: GUP-VEH0019 | S88: 45777 | T88: 638 | U88: VEHICLE | V88: T | W88: VIVEK B
...

Sheet ByVehicle
A1: Vehicle | B1: Division | C1: ADBLU | D1: FC WORK | E1: ROAD TAX | F1: RTO EXPENSE | G1: TYRE | H1: VEHICLE INSURANCE | I1: VEHICLE OUTSIDE SERVICES | J1: FY total | K1: FY lines | L1: Active on as-of | M1: All-time total | N1: All-time lines
A2: TN57AC3636 | B2: SOCKS | C2: =SUMIFS(CostLines!$L$2:$L$1055,CostLines!$A$2:$A$1055,$A2,CostLines!$C$2:$C$1055,C$1,CostLines!$I$2:$I$1055,README!$B$6) | D2: =SUMIFS(CostLines!$L$2:$L$1055,CostLines!$A$2:$A$1055,$A2,CostLines!$C$2:$C$1055,D$1,CostLines!$I$2:$I$1055,README!$B$6) | E2: =SUMIFS(CostLines!$L$2:$L$1055,CostLines!$A$2:$A$1055,$A2,CostLines!$C$2:$C$1055,E$1,CostLines!$I$2:$I$1055,README!$B$6) | F2: =SUMIFS(CostLines!$L$2:$L$1055,CostLines!$A$2:$A$1055,$A2,CostLines!$C$2:$C$1055,F$1,CostLines!$I$2:$I$1055,README!$B$6) | G2: =SUMIFS(CostLines!$L$2:$L$1055,CostLines!$A$2:$A$1055,$A2,CostLines!$C$2:$C$1055,G$1,CostLines!$I$2:$I$1055,README!$B$6) | H2: =SUMIFS(CostLines!$L$2:$L$1055,CostLines!$A$2:$A$1055,$A2,CostLines!$C$2:$C$1055,H$1,CostLines!$I$2:$I$1055,README!$B$6) | I2: =SUMIFS(CostLines!$L$2:$L$1055,CostLines!$A$2:$A$1055,$A2,CostLines!$C$2:$C$1055,I$1,CostLines!$I$2:$I$1055,README!$B$6) | J2: =SUM(C2:I2) | K2: =COUNTIFS(CostLines!$A$2:$A$1055,$A2,CostLines!$I$2:$I$1055,README!$B$6) | L2: =SUMIFS(CostLines!$L$2:$L$1055,CostLines!$A$2:$A$1055,$A2,CostLines!$P$2:$P$1055,1) | M2: =SUMIFS(CostLines!$L$2:$L$1055,CostLines!$A$2:$A$1055,$A2) | N2: =COUNTIFS(CostLines!$A$2:$A$1055,$A2)
A3: TN57AE3636 | B3: SOCKS | C3: =SUMIFS(CostLines!$L$2:$L$1055,CostLines!$A$2:$A$1055,$A3,CostLines!$C$2:$C$1055,C$1,CostLines!$I$2:$I$1055,README!$B$6) | D3: =SUMIFS(CostLines!$L$2:$L$1055,CostLines!$A$2:$A$1055,$A3,CostLines!$C$2:$C$1055,D$1,CostLines!$I$2:$I$1055,README!$B$6) | E3: =SUMIFS(CostLines!$L$2:$L$1055,CostLines!$A$2:$A$1055,$A3,CostLines!$C$2:$C$1055,E$1,CostLines!$I$2:$I$1055,README!$B$6) | F3: =SUMIFS(CostLines!$L$2:$L$1055,CostLines!$A$2:$A$1055,$A3,CostLines!$C$2:$C$1055,F$1,CostLines!$I$2:$I$1055,README!$B$6) | G3: =SUMIFS(CostLines!$L$2:$L$1055,CostLines!$A$2:$A$1055,$A3,CostLines!$C$2:$C$1055,G$1,CostLines!$I$2:$I$1055,README!$B$6) | H3: =SUMIFS(CostLines!$L$2:$L$1055,CostLines!$A$2:$A$1055,$A3,CostLines!$C$2:$C$1055,H$1,CostLines!$I$2:$I$1055,README!$B$6) | I3: =SUMIFS(CostLines!$L$2:$L$1055,CostLines!$A$2:$A$1055,$A3,CostLines!$C$2:$C$1055,I$1,CostLines!$I$2:$I$1055,README!$B$6) | J3: =SUM(C3:I3) | K3: =COUNTIFS(CostLines!$A$2:$A$1055,$A3,CostLines!$I$2:$I$1055,README!$B$6) | L3: =SUMIFS(CostLines!$L$2:$L$1055,CostLines!$A$2:$A$1055,$A3,CostLines!$P$2:$P$1055,1) | M3: =SUMIFS(CostLines!$L$2:$L$1055,CostLines!$A$2:$A$1055,$A3) | N3: =COUNTIFS(CostLines!$A$2:$A$1055,$A3)
A4: TN57AE9806 | B4: SOCKS | C4: =SUMIFS(CostLines!$L$2:$L$1055,CostLines!$A$2:$A$1055,$A4,CostLines!$C$2:$C$1055,C$1,CostLines!$I$2:$I$1055,README!$B$6) | D4: =SUMIFS(CostLines!$L$2:$L$1055,CostLines!$A$2:$A$1055,$A4,CostLines!$C$2:$C$1055,D$1,CostLines!$I$2:$I$1055,README!$B$6) | E4: =SUMIFS(CostLines!$L$2:$L$1055,CostLines!$A$2:$A$1055,$A4,CostLines!$C$2:$C$1055,E$1,CostLines!$I$2:$I$1055,README!$B$6) | F4: =SUMIFS(CostLines!$L$2:$L$1055,CostLines!$A$2:$A$1055,$A4,CostLines!$C$2:$C$1055,F$1,CostLines!$I$2:$I$1055,README!$B$6) | G4: =SUMIFS(CostLines!$L$2:$L$1055,CostLines!$A$2:$A$1055,$A4,CostLines!$C$2:$C$1055,G$1,CostLines!$I$2:$I$1055,README!$B$6) | H4: =SUMIFS(CostLines!$L$2:$L$1055,CostLines!$A$2:$A$1055,$A4,CostLines!$C$2:$C$1055,H$1,CostLines!$I$2:$I$1055,README!$B$6) | I4: =SUMIFS(CostLines!$L$2:$L$1055,CostLines!$A$2:$A$1055,$A4,CostLines!$C$2:$C$1055,I$1,CostLines!$I$2:$I$1055,README!$B$6) | J4: =SUM(C4:I4) | K4: =COUNTIFS(CostLines!$A$2:$A$1055,$A4,CostLines!$I$2:$I$1055,README!$B$6) | L4: =SUMIFS(CostLines!$L$2:$L$1055,CostLines!$A$2:$A$1055,$A4,CostLines!$P$2:$P$1055,1) | M4: =SUMIFS(CostLines!$L$2:$L$1055,CostLines!$A$2:$A$1055,$A4) | N4: =COUNTIFS(CostLines!$A$2:$A$1055,$A4)
A5: TN57AF3636 | B5: SOCKS | C5: =SUMIFS(CostLines!$L$2:$L$1055,CostLines!$A$2:$A$1055,$A5,CostLines!$C$2:$C$1055,C$1,CostLines!$I$2:$I$1055,README!$B$6) | D5: =SUMIFS(CostLines!$L$2:$L$1055,CostLines!$A$2:$A$1055,$A5,CostLines!$C$2:$C$1055,D$1,CostLines!$I$2:$I$1055,README!$B$6) | E5: =SUMIFS(CostLines!$L$2:$L$1055,CostLines!$A$2:$A$1055,$A5,CostLines!$C$2:$C$1055,E$1,CostLines!$I$2:$I$1055,README!$B$6) | F5: =SUMIFS(CostLines!$L$2:$L$1055,CostLines!$A$2:$A$1055,$A5,CostLines!$C$2:$C$1055,F$1,CostLines!$I$2:$I$1055,README!$B$6) | G5: =SUMIFS(CostLines!$L$2:$L$1055,CostLines!$A$2:$A$1055,$A5,CostLines!$C$2:$C$1055,G$1,CostLines!$I$2:$I$1055,README!$B$6) | H5: =SUMIFS(CostLines!$L$2:$L$1055,CostLines!$A$2:$A$1055,$A5,CostLines!$C$2:$C$1055,H$1,CostLines!$I$2:$I$1055,README!$B$6) | I5: =SUMIFS(CostLines!$L$2:$L$1055,CostLines!$A$2:$A$1055,$A5,CostLines!$C$2:$C$1055,I$1,CostLines!$I$2:$I$1055,README!$B$6) | J5: =SUM(C5:I5) | K5: =COUNTIFS(CostLines!$A$2:$A$1055,$A5,CostLines!$I$2:$I$1055,README!$B$6) | L5: =SUMIFS(CostLines!$L$2:$L$1055,CostLines!$A$2:$A$1055,$A5,CostLines!$P$2:$P$1055,1) | M5: =SUMIFS(CostLines!$L$2:$L$1055,CostLines!$A$2:$A$1055,$A5) | N5: =COUNTIFS(CostLines!$A$2:$A$1055,$A5)
A6: TN57AH3636 | B6: SOCKS | C6: =SUMIFS(CostLines!$L$2:$L$1055,CostLines!$A$2:$A$1055,$A6,CostLines!$C$2:$C$1055,C$1,CostLines!$I$2:$I$1055,README!$B$6) | D6: =SUMIFS(CostLines!$L$2:$L$1055,CostLines!$A$2:$A$1055,$A6,CostLines!$C$2:$C$1055,D$1,CostLines!$I$2:$I$1055,README!$B$6) | E6: =SUMIFS(CostLines!$L$2:$L$1055,CostLines!$A$2:$A$1055,$A6,CostLines!$C$2:$C$1055,E$1,CostLines!$I$2:$I$1055,README!$B$6) | F6: =SUMIFS(CostLines!$L$2:$L$1055,CostLines!$A$2:$A$1055,$A6,CostLines!$C$2:$C$1055,F$1,CostLines!$I$2:$I$1055,README!$B$6) | G6: =SUMIFS(CostLines!$L$2:$L$1055,CostLines!$A$2:$A$1055,$A6,CostLines!$C$2:$C$1055,G$1,CostLines!$I$2:$I$1055,README!$B$6) | H6: =SUMIFS(CostLines!$L$2:$L$1055,CostLines!$A$2:$A$1055,$A6,CostLines!$C$2:$C$1055,H$1,CostLines!$I$2:$I$1055,README!$B$6) | I6: =SUMIFS(CostLines!$L$2:$L$1055,CostLines!$A$2:$A$1055,$A6,CostLines!$C$2:$C$1055,I$1,CostLines!$I$2:$I$1055,README!$B$6) | J6: =SUM(C6:I6) | K6: =COUNTIFS(CostLines!$A$2:$A$1055,$A6,CostLines!$I$2:$I$1055,README!$B$6) | L6: =SUMIFS(CostLines!$L$2:$L$1055,CostLines!$A$2:$A$1055,$A6,CostLines!$P$2:$P$1055,1) | M6: =SUMIFS(CostLines!$L$2:$L$1055,CostLines!$A$2:$A$1055,$A6) | N6: =COUNTIFS(CostLines!$A$2:$A$1055,$A6)
A7: TN57AK3636 | B7: GENERAL | C7: =SUMIFS(CostLines!$L$2:$L$1055,CostLines!$A$2:$A$1055,$A7,CostLines!$C$2:$C$1055,C$1,CostLines!$I$2:$I$1055,README!$B$6) | D7: =SUMIFS(CostLines!$L$2:$L$1055,CostLines!$A$2:$A$1055,$A7,CostLines!$C$2:$C$1055,D$1,CostLines!$I$2:$I$1055,README!$B$6) | E7: =SUMIFS(CostLines!$L$2:$L$1055,CostLines!$A$2:$A$1055,$A7,CostLines!$C$2:$C$1055,E$1,CostLines!$I$2:$I$1055,README!$B$6) | F7: =SUMIFS(CostLines!$L$2:$L$1055,CostLines!$A$2:$A$1055,$A7,CostLines!$C$2:$C$1055,F$1,CostLines!$I$2:$I$1055,README!$B$6) | G7: =SUMIFS(CostLines!$L$2:$L$1055,CostLines!$A$2:$A$1055,$A7,CostLines!$C$2:$C$1055,G$1,CostLines!$I$2:$I$1055,README!$B$6) | H7: =SUMIFS(CostLines!$L$2:$L$1055,CostLines!$A$2:$A$1055,$A7,CostLines!$C$2:$C$1055,H$1,CostLines!$I$2:$I$1055,README!$B$6) | I7: =SUMIFS(CostLines!$L$2:$L$1055,CostLines!$A$2:$A$1055,$A7,CostLines!$C$2:$C$1055,I$1,CostLines!$I$2:$I$1055,README!$B$6) | J7: =SUM(C7:I7) | K7: =COUNTIFS(CostLines!$A$2:$A$1055,$A7,CostLines!$I$2:$I$1055,README!$B$6) | L7: =SUMIFS(CostLines!$L$2:$L$1055,CostLines!$A$2:$A$1055,$A7,CostLines!$P$2:$P$1055,1) | M7: =SUMIFS(CostLines!$L$2:$L$1055,CostLines!$A$2:$A$1055,$A7) | N7: =COUNTIFS(CostLines!$A$2:$A$1055,$A7)
A8: TN57AM3636 | B8: SOCKS | C8: =SUMIFS(CostLines!$L$2:$L$1055,CostLines!$A$2:$A$1055,$A8,CostLines!$C$2:$C$1055,C$1,CostLines!$I$2:$I$1055,README!$B$6) | D8: =SUMIFS(CostLines!$L$2:$L$1055,CostLines!$A$2:$A$1055,$A8,CostLines!$C$2:$C$1055,D$1,CostLines!$I$2:$I$1055,README!$B$6) | E8: =SUMIFS(CostLines!$L$2:$L$1055,CostLines!$A$2:$A$1055,$A8,CostLines!$C$2:$C$1055,E$1,CostLines!$I$2:$I$1055,README!$B$6) | F8: =SUMIFS(CostLines!$L$2:$L$1055,CostLines!$A$2:$A$1055,$A8,CostLines!$C$2:$C$1055,F$1,CostLines!$I$2:$I$1055,README!$B$6) | G8: =SUMIFS(CostLines!$L$2:$L$1055,CostLines!$A$2:$A$1055,$A8,CostLines!$C$2:$C$1055,G$1,CostLines!$I$2:$I$1055,README!$B$6) | H8: =SUMIFS(CostLines!$L$2:$L$1055,CostLines!$A$2:$A$1055,$A8,CostLines!$C$2:$C$1055,H$1,CostLines!$I$2:$I$1055,README!$B$6) | I8: =SUMIFS(CostLines!$L$2:$L$1055,CostLines!$A$2:$A$1055,$A8,CostLines!$C$2:$C$1055,I$1,CostLines!$I$2:$I$1055,README!$B$6) | J8: =SUM(C8:I8) | K8: =COUNTIFS(CostLines!$A$2:$A$1055,$A8,CostLines!$I$2:$I$1055,README!$B$6) | L8: =SUMIFS(CostLines!$L$2:$L$1055,CostLines!$A$2:$A$1055,$A8,CostLines!$P$2:$P$1055,1) | M8: =SUMIFS(CostLines!$L$2:$L$1055,CostLines!$A$2:$A$1055,$A8) | N8: =COUNTIFS(CostLines!$A$2:$A$1055,$A8)
A9: TN57AU3636 | B9: SOCKS | C9: =SUMIFS(CostLines!$L$2:$L$1055,CostLines!$A$2:$A$1055,$A9,CostLines!$C$2:$C$1055,C$1,CostLines!$I$2:$I$1055,README!$B$6) | D9: =SUMIFS(CostLines!$L$2:$L$1055,CostLines!$A$2:$A$1055,$A9,CostLines!$C$2:$C$1055,D$1,CostLines!$I$2:$I$1055,README!$B$6) | E9: =SUMIFS(CostLines!$L$2:$L$1055,CostLines!$A$2:$A$1055,$A9,CostLines!$C$2:$C$1055,E$1,CostLines!$I$2:$I$1055,README!$B$6) | F9: =SUMIFS(CostLines!$L$2:$L$1055,CostLines!$A$2:$A$1055,$A9,CostLines!$C$2:$C$1055,F$1,CostLines!$I$2:$I$1055,README!$B$6) | G9: =SUMIFS(CostLines!$L$2:$L$1055,CostLines!$A$2:$A$1055,$A9,CostLines!$C$2:$C$1055,G$1,CostLines!$I$2:$I$1055,README!$B$6) | H9: =SUMIFS(CostLines!$L$2:$L$1055,CostLines!$A$2:$A$1055,$A9,CostLines!$C$2:$C$1055,H$1,CostLines!$I$2:$I$1055,README!$B$6) | I9: =SUMIFS(CostLines!$L$2:$L$1055,CostLines!$A$2:$A$1055,$A9,CostLines!$C$2:$C$1055,I$1,CostLines!$I$2:$I$1055,README!$B$6) | J9: =SUM(C9:I9) | K9: =COUNTIFS(CostLines!$A$2:$A$1055,$A9,CostLines!$I$2:$I$1055,README!$B$6) | L9: =SUMIFS(CostLines!$L$2:$L$1055,CostLines!$A$2:$A$1055,$A9,CostLines!$P$2:$P$1055,1) | M9: =SUMIFS(CostLines!$L$2:$L$1055,CostLines!$A$2:$A$1055,$A9) | N9: =COUNTIFS(CostLines!$A$2:$A$1055,$A9)
A10: TN57BC3636 | B10: SOCKS | C10: =SUMIFS(CostLines!$L$2:$L$1055,CostLines!$A$2:$A$1055,$A10,CostLines!$C$2:$C$1055,C$1,CostLines!$I$2:$I$1055,README!$B$6) | D10: =SUMIFS(CostLines!$L$2:$L$1055,CostLines!$A$2:$A$1055,$A10,CostLines!$C$2:$C$1055,D$1,CostLines!$I$2:$I$1055,README!$B$6) | E10: =SUMIFS(CostLines!$L$2:$L$1055,CostLines!$A$2:$A$1055,$A10,CostLines!$C$2:$C$1055,E$1,CostLines!$I$2:$I$1055,README!$B$6) | F10: =SUMIFS(CostLines!$L$2:$L$1055,CostLines!$A$2:$A$1055,$A10,CostLines!$C$2:$C$1055,F$1,CostLines!$I$2:$I$1055,README!$B$6) | G10: =SUMIFS(CostLines!$L$2:$L$1055,CostLines!$A$2:$A$1055,$A10,CostLines!$C$2:$C$1055,G$1,CostLines!$I$2:$I$1055,README!$B$6) | H10: =SUMIFS(CostLines!$L$2:$L$1055,CostLines!$A$2:$A$1055,$A10,CostLines!$C$2:$C$1055,H$1,CostLines!$I$2:$I$1055,README!$B$6) | I10: =SUMIFS(CostLines!$L$2:$L$1055,CostLines!$A$2:$A$1055,$A10,CostLines!$C$2:$C$1055,I$1,CostLines!$I$2:$I$1055,README!$B$6) | J10: =SUM(C10:I10) | K10: =COUNTIFS(CostLines!$A$2:$A$1055,$A10,CostLines!$I$2:$I$1055,README!$B$6) | L10: =SUMIFS(CostLines!$L$2:$L$1055,CostLines!$A$2:$A$1055,$A10,CostLines!$P$2:$P$1055,1) | M10: =SUMIFS(CostLines!$L$2:$L$1055,CostLines!$A$2:$A$1055,$A10) | N10: =COUNTIFS(CostLines!$A$2:$A$1055,$A10)
A11: TN57BE3636 | B11: SOCKS | C11: =SUMIFS(CostLines!$L$2:$L$1055,CostLines!$A$2:$A$1055,$A11,CostLines!$C$2:$C$1055,C$1,CostLines!$I$2:$I$1055,README!$B$6) | D11: =SUMIFS(CostLines!$L$2:$L$1055,CostLines!$A$2:$A$1055,$A11,CostLines!$C$2:$C$1055,D$1,CostLines!$I$2:$I$1055,README!$B$6) | E11: =SUMIFS(CostLines!$L$2:$L$1055,CostLines!$A$2:$A$1055,$A11,CostLines!$C$2:$C$1055,E$1,CostLines!$I$2:$I$1055,README!$B$6) | F11: =SUMIFS(CostLines!$L$2:$L$1055,CostLines!$A$2:$A$1055,$A11,CostLines!$C$2:$C$1055,F$1,CostLines!$I$2:$I$1055,README!$B$6) | G11: =SUMIFS(CostLines!$L$2:$L$1055,CostLines!$A$2:$A$1055,$A11,CostLines!$C$2:$C$1055,G$1,CostLines!$I$2:$I$1055,README!$B$6) | H11: =SUMIFS(CostLines!$L$2:$L$1055,CostLines!$A$2:$A$1055,$A11,CostLines!$C$2:$C$1055,H$1,CostLines!$I$2:$I$1055,README!$B$6) | I11: =SUMIFS(CostLines!$L$2:$L$1055,CostLines!$A$2:$A$1055,$A11,CostLines!$C$2:$C$1055,I$1,CostLines!$I$2:$I$1055,README!$B$6) | J11: =SUM(C11:I11) | K11: =COUNTIFS(CostLines!$A$2:$A$1055,$A11,CostLines!$I$2:$I$1055,README!$B$6) | L11: =SUMIFS(CostLines!$L$2:$L$1055,CostLines!$A$2:$A$1055,$A11,CostLines!$P$2:$P$1055,1) | M11: =SUMIFS(CostLines!$L$2:$L$1055,CostLines!$A$2:$A$1055,$A11) | N11: =COUNTIFS(CostLines!$A$2:$A$1055,$A11)
A12: TN57BH3636 | B12: SOCKS | C12: =SUMIFS(CostLines!$L$2:$L$1055,CostLines!$A$2:$A$1055,$A12,CostLines!$C$2:$C$1055,C$1,CostLines!$I$2:$I$1055,README!$B$6) | D12: =SUMIFS(CostLines!$L$2:$L$1055,CostLines!$A$2:$A$1055,$A12,CostLines!$C$2:$C$1055,D$1,CostLines!$I$2:$I$1055,README!$B$6) | E12: =SUMIFS(CostLines!$L$2:$L$1055,CostLines!$A$2:$A$1055,$A12,CostLines!$C$2:$C$1055,E$1,CostLines!$I$2:$I$1055,README!$B$6) | F12: =SUMIFS(CostLines!$L$2:$L$1055,CostLines!$A$2:$A$1055,$A12,CostLines!$C$2:$C$1055,F$1,CostLines!$I$2:$I$1055,README!$B$6) | G12: =SUMIFS(CostLines!$L$2:$L$1055,CostLines!$A$2:$A$1055,$A12,CostLines!$C$2:$C$1055,G$1,CostLines!$I$2:$I$1055,README!$B$6) | H12: =SUMIFS(CostLines!$L$2:$L$1055,CostLines!$A$2:$A$1055,$A12,CostLines!$C$2:$C$1055,H$1,CostLines!$I$2:$I$1055,README!$B$6) | I12: =SUMIFS(CostLines!$L$2:$L$1055,CostLines!$A$2:$A$1055,$A12,CostLines!$C$2:$C$1055,I$1,CostLines!$I$2:$I$1055,README!$B$6) | J12: =SUM(C12:I12) | K12: =COUNTIFS(CostLines!$A$2:$A$1055,$A12,CostLines!$I$2:$I$1055,README!$B$6) | L12: =SUMIFS(CostLines!$L$2:$L$1055,CostLines!$A$2:$A$1055,$A12,CostLines!$P$2:$P$1055,1) | M12: =SUMIFS(CostLines!$L$2:$L$1055,CostLines!$A$2:$A$1055,$A12) | N12: =COUNTIFS(CostLines!$A$2:$A$1055,$A12)
A13: TN57BL3636 | B13: SOCKS | C13: =SUMIFS(CostLines!$L$2:$L$1055,CostLines!$A$2:$A$1055,$A13,CostLines!$C$2:$C$1055,C$1,CostLines!$I$2:$I$1055,README!$B$6) | D13: =SUMIFS(CostLines!$L$2:$L$1055,CostLines!$A$2:$A$1055,$A13,CostLines!$C$2:$C$1055,D$1,CostLines!$I$2:$I$1055,README!$B$6) | E13: =SUMIFS(CostLines!$L$2:$L$1055,CostLines!$A$2:$A$1055,$A13,CostLines!$C$2:$C$1055,E$1,CostLines!$I$2:$I$1055,README!$B$6) | F13: =SUMIFS(CostLines!$L$2:$L$1055,CostLines!$A$2:$A$1055,$A13,CostLines!$C$2:$C$1055,F$1,CostLines!$I$2:$I$1055,README!$B$6) | G13: =SUMIFS(CostLines!$L$2:$L$1055,CostLines!$A$2:$A$1055,$A13,CostLines!$C$2:$C$1055,G$1,CostLines!$I$2:$I$1055,README!$B$6) | H13: =SUMIFS(CostLines!$L$2:$L$1055,CostLines!$A$2:$A$1055,$A13,CostLines!$C$2:$C$1055,H$1,CostLines!$I$2:$I$1055,README!$B$6) | I13: =SUMIFS(CostLines!$L$2:$L$1055,CostLines!$A$2:$A$1055,$A13,CostLines!$C$2:$C$1055,I$1,CostLines!$I$2:$I$1055,README!$B$6) | J13: =SUM(C13:I13) | K13: =COUNTIFS(CostLines!$A$2:$A$1055,$A13,CostLines!$I$2:$I$1055,README!$B$6) | L13: =SUMIFS(CostLines!$L$2:$L$1055,CostLines!$A$2:$A$1055,$A13,CostLines!$P$2:$P$1055,1) | M13: =SUMIFS(CostLines!$L$2:$L$1055,CostLines!$A$2:$A$1055,$A13) | N13: =COUNTIFS(CostLines!$A$2:$A$1055,$A13)
... A43: TN57CL3636 | B43: GENERAL | C43: =SUMIFS(CostLines!$L$2:$L$1055,CostLines!$A$2:$A$1055,$A43,CostLines!$C$2:$C$1055,C$1,CostLines!$I$2:$I$1055,README!$B$6) | D43: =SUMIFS(CostLines!$L$2:$L$1055,CostLines!$A$2:$A$1055,$A43,CostLines!$C$2:$C$1055,D$1,CostLines!$I$2:$I$1055,README!$B$6) | E43: =SUMIFS(CostLines!$L$2:$L$1055,CostLines!$A$2:$A$1055,$A43,CostLines!$C$2:$C$1055,E$1,CostLines!$I$2:$I$1055,README!$B$6) | F43: =SUMIFS(CostLines!$L$2:$L$1055,CostLines!$A$2:$A$1055,$A43,CostLines!$C$2:$C$1055,F$1,CostLines!$I$2:$I$1055,README!$B$6) | G43: =SUMIFS(CostLines!$L$2:$L$1055,CostLines!$A$2:$A$1055,$A43,CostLines!$C$2:$C$1055,G$1,CostLines!$I$2:$I$1055,README!$B$6) | H43: =SUMIFS(CostLines!$L$2:$L$1055,CostLines!$A$2:$A$1055,$A43,CostLines!$C$2:$C$1055,H$1,CostLines!$I$2:$I$1055,README!$B$6) | I43: =SUMIFS(CostLines!$L$2:$L$1055,CostLines!$A$2:$A$1055,$A43,CostLines!$C$2:$C$1055,I$1,CostLines!$I$2:$I$1055,README!$B$6) | J43: =SUM(C43:I43) | K43: =COUNTIFS(CostLines!$A$2:$A$1055,$A43,CostLines!$I$2:$I$1055,README!$B$6) | L43: =SUMIFS(CostLines!$L$2:$L$1055,CostLines!$A$2:$A$1055,$A43,CostLines!$P$2:$P$1055,1) | M43: =SUMIFS(CostLines!$L$2:$L$1055,CostLines!$A$2:$A$1055,$A43) | N43: =COUNTIFS(CostLines!$A$2:$A$1055,$A43)
A44: TN57CM3636 | C44: =SUMIFS(CostLines!$L$2:$L$1055,CostLines!$A$2:$A$1055,$A44,CostLines!$C$2:$C$1055,C$1,CostLines!$I$2:$I$1055,README!$B$6) | D44: =SUMIFS(CostLines!$L$2:$L$1055,CostLines!$A$2:$A$1055,$A44,CostLines!$C$2:$C$1055,D$1,CostLines!$I$2:$I$1055,README!$B$6) | E44: =SUMIFS(CostLines!$L$2:$L$1055,CostLines!$A$2:$A$1055,$A44,CostLines!$C$2:$C$1055,E$1,CostLines!$I$2:$I$1055,README!$B$6) | F44: =SUMIFS(CostLines!$L$2:$L$1055,CostLines!$A$2:$A$1055,$A44,CostLines!$C$2:$C$1055,F$1,CostLines!$I$2:$I$1055,README!$B$6) | G44: =SUMIFS(CostLines!$L$2:$L$1055,CostLines!$A$2:$A$1055,$A44,CostLines!$C$2:$C$1055,G$1,CostLines!$I$2:$I$1055,README!$B$6) | H44: =SUMIFS(CostLines!$L$2:$L$1055,CostLines!$A$2:$A$1055,$A44,CostLines!$C$2:$C$1055,H$1,CostLines!$I$2:$I$1055,README!$B$6) | I44: =SUMIFS(CostLines!$L$2:$L$1055,CostLines!$A$2:$A$1055,$A44,CostLines!$C$2:$C$1055,I$1,CostLines!$I$2:$I$1055,README!$B$6) | J44: =SUM(C44:I44) | K44: =COUNTIFS(CostLines!$A$2:$A$1055,$A44,CostLines!$I$2:$I$1055,README!$B$6) | L44: =SUMIFS(CostLines!$L$2:$L$1055,CostLines!$A$2:$A$1055,$A44,CostLines!$P$2:$P$1055,1) | M44: =SUMIFS(CostLines!$L$2:$L$1055,CostLines!$A$2:$A$1055,$A44) | N44: =COUNTIFS(CostLines!$A$2:$A$1055,$A44)
A45: TN58BJ3434 | B45: WOVEN | C45: =SUMIFS(CostLines!$L$2:$L$1055,CostLines!$A$2:$A$1055,$A45,CostLines!$C$2:$C$1055,C$1,CostLines!$I$2:$I$1055,README!$B$6) | D45: =SUMIFS(CostLines!$L$2:$L$1055,CostLines!$A$2:$A$1055,$A45,CostLines!$C$2:$C$1055,D$1,CostLines!$I$2:$I$1055,README!$B$6) | E45: =SUMIFS(CostLines!$L$2:$L$1055,CostLines!$A$2:$A$1055,$A45,CostLines!$C$2:$C$1055,E$1,CostLines!$I$2:$I$1055,README!$B$6) | F45: =SUMIFS(CostLines!$L$2:$L$1055,CostLines!$A$2:$A$1055,$A45,CostLines!$C$2:$C$1055,F$1,CostLines!$I$2:$I$1055,README!$B$6) | G45: =SUMIFS(CostLines!$L$2:$L$1055,CostLines!$A$2:$A$1055,$A45,CostLines!$C$2:$C$1055,G$1,CostLines!$I$2:$I$1055,README!$B$6) | H45: =SUMIFS(CostLines!$L$2:$L$1055,CostLines!$A$2:$A$1055,$A45,CostLines!$C$2:$C$1055,H$1,CostLines!$I$2:$I$1055,README!$B$6) | I45: =SUMIFS(CostLines!$L$2:$L$1055,CostLines!$A$2:$A$1055,$A45,CostLines!$C$2:$C$1055,I$1,CostLines!$I$2:$I$1055,README!$B$6) | J45: =SUM(C45:I45) | K45: =COUNTIFS(CostLines!$A$2:$A$1055,$A45,CostLines!$I$2:$I$1055,README!$B$6) | L45: =SUMIFS(CostLines!$L$2:$L$1055,CostLines!$A$2:$A$1055,$A45,CostLines!$P$2:$P$1055,1) | M45: =SUMIFS(CostLines!$L$2:$L$1055,CostLines!$A$2:$A$1055,$A45) | N45: =COUNTIFS(CostLines!$A$2:$A$1055,$A45)
A46: TN58BJ3636 | B46: SOCKS | C46: =SUMIFS(CostLines!$L$2:$L$1055,CostLines!$A$2:$A$1055,$A46,CostLines!$C$2:$C$1055,C$1,CostLines!$I$2:$I$1055,README!$B$6) | D46: =SUMIFS(CostLines!$L$2:$L$1055,CostLines!$A$2:$A$1055,$A46,CostLines!$C$2:$C$1055,D$1,CostLines!$I$2:$I$1055,README!$B$6) | E46: =SUMIFS(CostLines!$L$2:$L$1055,CostLines!$A$2:$A$1055,$A46,CostLines!$C$2:$C$1055,E$1,CostLines!$I$2:$I$1055,README!$B$6) | F46: =SUMIFS(CostLines!$L$2:$L$1055,CostLines!$A$2:$A$1055,$A46,CostLines!$C$2:$C$1055,F$1,CostLines!$I$2:$I$1055,README!$B$6) | G46: =SUMIFS(CostLines!$L$2:$L$1055,CostLines!$A$2:$A$1055,$A46,CostLines!$C$2:$C$1055,G$1,CostLines!$I$2:$I$1055,README!$B$6) | H46: =SUMIFS(CostLines!$L$2:$L$1055,CostLines!$A$2:$A$1055,$A46,CostLines!$C$2:$C$1055,H$1,CostLines!$I$2:$I$1055,README!$B$6) | I46: =SUMIFS(CostLines!$L$2:$L$1055,CostLines!$A$2:$A$1055,$A46,CostLines!$C$2:$C$1055,I$1,CostLines!$I$2:$I$1055,README!$B$6) | J46: =SUM(C46:I46) | K46: =COUNTIFS(CostLines!$A$2:$A$1055,$A46,CostLines!$I$2:$I$1055,README!$B$6) | L46: =SUMIFS(CostLines!$L$2:$L$1055,CostLines!$A$2:$A$1055,$A46,CostLines!$P$2:$P$1055,1) | M46: =SUMIFS(CostLines!$L$2:$L$1055,CostLines!$A$2:$A$1055,$A46) | N46: =COUNTIFS(CostLines!$A$2:$A$1055,$A46)
A47: TN58BK3434 | B47: WOVEN | C47: =SUMIFS(CostLines!$L$2:$L$1055,CostLines!$A$2:$A$1055,$A47,CostLines!$C$2:$C$1055,C$1,CostLines!$I$2:$I$1055,README!$B$6) | D47: =SUMIFS(CostLines!$L$2:$L$1055,CostLines!$A$2:$A$1055,$A47,CostLines!$C$2:$C$1055,D$1,CostLines!$I$2:$I$1055,README!$B$6) | E47: =SUMIFS(CostLines!$L$2:$L$1055,CostLines!$A$2:$A$1055,$A47,CostLines!$C$2:$C$1055,E$1,CostLines!$I$2:$I$1055,README!$B$6) | F47: =SUMIFS(CostLines!$L$2:$L$1055,CostLines!$A$2:$A$1055,$A47,CostLines!$C$2:$C$1055,F$1,CostLines!$I$2:$I$1055,README!$B$6) | G47: =SUMIFS(CostLines!$L$2:$L$1055,CostLines!$A$2:$A$1055,$A47,CostLines!$C$2:$C$1055,G$1,CostLines!$I$2:$I$1055,README!$B$6) | H47: =SUMIFS(CostLines!$L$2:$L$1055,CostLines!$A$2:$A$1055,$A47,CostLines!$C$2:$C$1055,H$1,CostLines!$I$2:$I$1055,README!$B$6) | I47: =SUMIFS(CostLines!$L$2:$L$1055,CostLines!$A$2:$A$1055,$A47,CostLines!$C$2:$C$1055,I$1,CostLines!$I$2:$I$1055,README!$B$6) | J47: =SUM(C47:I47) | K47: =COUNTIFS(CostLines!$A$2:$A$1055,$A47,CostLines!$I$2:$I$1055,README!$B$6) | L47: =SUMIFS(CostLines!$L$2:$L$1055,CostLines!$A$2:$A$1055,$A47,CostLines!$P$2:$P$1055,1) | M47: =SUMIFS(CostLines!$L$2:$L$1055,CostLines!$A$2:$A$1055,$A47) | N47: =COUNTIFS(CostLines!$A$2:$A$1055,$A47)
A48: TN58BK3636 | B48: SOCKS | C48: =SUMIFS(CostLines!$L$2:$L$1055,CostLines!$A$2:$A$1055,$A48,CostLines!$C$2:$C$1055,C$1,CostLines!$I$2:$I$1055,README!$B$6) | D48: =SUMIFS(CostLines!$L$2:$L$1055,CostLines!$A$2:$A$1055,$A48,CostLines!$C$2:$C$1055,D$1,CostLines!$I$2:$I$1055,README!$B$6) | E48: =SUMIFS(CostLines!$L$2:$L$1055,CostLines!$A$2:$A$1055,$A48,CostLines!$C$2:$C$1055,E$1,CostLines!$I$2:$I$1055,README!$B$6) | F48: =SUMIFS(CostLines!$L$2:$L$1055,CostLines!$A$2:$A$1055,$A48,CostLines!$C$2:$C$1055,F$1,CostLines!$I$2:$I$1055,README!$B$6) | G48: =SUMIFS(CostLines!$L$2:$L$1055,CostLines!$A$2:$A$1055,$A48,CostLines!$C$2:$C$1055,G$1,CostLines!$I$2:$I$1055,README!$B$6) | H48: =SUMIFS(CostLines!$L$2:$L$1055,CostLines!$A$2:$A$1055,$A48,CostLines!$C$2:$C$1055,H$1,CostLines!$I$2:$I$1055,README!$B$6) | I48: =SUMIFS(CostLines!$L$2:$L$1055,CostLines!$A$2:$A$1055,$A48,CostLines!$C$2:$C$1055,I$1,CostLines!$I$2:$I$1055,README!$B$6) | J48: =SUM(C48:I48) | K48: =COUNTIFS(CostLines!$A$2:$A$1055,$A48,CostLines!$I$2:$I$1055,README!$B$6) | L48: =SUMIFS(CostLines!$L$2:$L$1055,CostLines!$A$2:$A$1055,$A48,CostLines!$P$2:$P$1055,1) | M48: =SUMIFS(CostLines!$L$2:$L$1055,CostLines!$A$2:$A$1055,$A48) | N48: =COUNTIFS(CostLines!$A$2:$A$1055,$A48)
A49: TN58BL3434 | B49: WOVEN | C49: =SUMIFS(CostLines!$L$2:$L$1055,CostLines!$A$2:$A$1055,$A49,CostLines!$C$2:$C$1055,C$1,CostLines!$I$2:$I$1055,README!$B$6) | D49: =SUMIFS(CostLines!$L$2:$L$1055,CostLines!$A$2:$A$1055,$A49,CostLines!$C$2:$C$1055,D$1,CostLines!$I$2:$I$1055,README!$B$6) | E49: =SUMIFS(CostLines!$L$2:$L$1055,CostLines!$A$2:$A$1055,$A49,CostLines!$C$2:$C$1055,E$1,CostLines!$I$2:$I$1055,README!$B$6) | F49: =SUMIFS(CostLines!$L$2:$L$1055,CostLines!$A$2:$A$1055,$A49,CostLines!$C$2:$C$1055,F$1,CostLines!$I$2:$I$1055,README!$B$6) | G49: =SUMIFS(CostLines!$L$2:$L$1055,CostLines!$A$2:$A$1055,$A49,CostLines!$C$2:$C$1055,G$1,CostLines!$I$2:$I$1055,README!$B$6) | H49: =SUMIFS(CostLines!$L$2:$L$1055,CostLines!$A$2:$A$1055,$A49,CostLines!$C$2:$C$1055,H$1,CostLines!$I$2:$I$1055,README!$B$6) | I49: =SUMIFS(CostLines!$L$2:$L$1055,CostLines!$A$2:$A$1055,$A49,CostLines!$C$2:$C$1055,I$1,CostLines!$I$2:$I$1055,README!$B$6) | J49: =SUM(C49:I49) | K49: =COUNTIFS(CostLines!$A$2:$A$1055,$A49,CostLines!$I$2:$I$1055,README!$B$6) | L49: =SUMIFS(CostLines!$L$2:$L$1055,CostLines!$A$2:$A$1055,$A49,CostLines!$P$2:$P$1055,1) | M49: =SUMIFS(CostLines!$L$2:$L$1055,CostLines!$A$2:$A$1055,$A49) | N49: =COUNTIFS(CostLines!$A$2:$A$1055,$A49)
A50: TN58BL3636 | B50: SOCKS | C50: =SUMIFS(CostLines!$L$2:$L$1055,CostLines!$A$2:$A$1055,$A50,CostLines!$C$2:$C$1055,C$1,CostLines!$I$2:$I$1055,README!$B$6) | D50: =SUMIFS(CostLines!$L$2:$L$1055,CostLines!$A$2:$A$1055,$A50,CostLines!$C$2:$C$1055,D$1,CostLines!$I$2:$I$1055,README!$B$6) | E50: =SUMIFS(CostLines!$L$2:$L$1055,CostLines!$A$2:$A$1055,$A50,CostLines!$C$2:$C$1055,E$1,CostLines!$I$2:$I$1055,README!$B$6) | F50: =SUMIFS(CostLines!$L$2:$L$1055,CostLines!$A$2:$A$1055,$A50,CostLines!$C$2:$C$1055,F$1,CostLines!$I$2:$I$1055,README!$B$6) | G50: =SUMIFS(CostLines!$L$2:$L$1055,CostLines!$A$2:$A$1055,$A50,CostLines!$C$2:$C$1055,G$1,CostLines!$I$2:$I$1055,README!$B$6) | H50: =SUMIFS(CostLines!$L$2:$L$1055,CostLines!$A$2:$A$1055,$A50,CostLines!$C$2:$C$1055,H$1,CostLines!$I$2:$I$1055,README!$B$6) | I50: =SUMIFS(CostLines!$L$2:$L$1055,CostLines!$A$2:$A$1055,$A50,CostLines!$C$2:$C$1055,I$1,CostLines!$I$2:$I$1055,README!$B$6) | J50: =SUM(C50:I50) | K50: =COUNTIFS(CostLines!$A$2:$A$1055,$A50,CostLines!$I$2:$I$1055,README!$B$6) | L50: =SUMIFS(CostLines!$L$2:$L$1055,CostLines!$A$2:$A$1055,$A50,CostLines!$P$2:$P$1055,1) | M50: =SUMIFS(CostLines!$L$2:$L$1055,CostLines!$A$2:$A$1055,$A50) | N50: =COUNTIFS(CostLines!$A$2:$A$1055,$A50)
A51: TN58BM3434 | B51: WOVEN | C51: =SUMIFS(CostLines!$L$2:$L$1055,CostLines!$A$2:$A$1055,$A51,CostLines!$C$2:$C$1055,C$1,CostLines!$I$2:$I$1055,README!$B$6) | D51: =SUMIFS(CostLines!$L$2:$L$1055,CostLines!$A$2:$A$1055,$A51,CostLines!$C$2:$C$1055,D$1,CostLines!$I$2:$I$1055,README!$B$6) | E51: =SUMIFS(CostLines!$L$2:$L$1055,CostLines!$A$2:$A$1055,$A51,CostLines!$C$2:$C$1055,E$1,CostLines!$I$2:$I$1055,README!$B$6) | F51: =SUMIFS(CostLines!$L$2:$L$1055,CostLines!$A$2:$A$1055,$A51,CostLines!$C$2:$C$1055,F$1,CostLines!$I$2:$I$1055,README!$B$6) | G51: =SUMIFS(CostLines!$L$2:$L$1055,CostLines!$A$2:$A$1055,$A51,CostLines!$C$2:$C$1055,G$1,CostLines!$I$2:$I$1055,README!$B$6) | H51: =SUMIFS(CostLines!$L$2:$L$1055,CostLines!$A$2:$A$1055,$A51,CostLines!$C$2:$C$1055,H$1,CostLines!$I$2:$I$1055,README!$B$6) | I51: =SUMIFS(CostLines!$L$2:$L$1055,CostLines!$A$2:$A$1055,$A51,CostLines!$C$2:$C$1055,I$1,CostLines!$I$2:$I$1055,README!$B$6) | J51: =SUM(C51:I51) | K51: =COUNTIFS(CostLines!$A$2:$A$1055,$A51,CostLines!$I$2:$I$1055,README!$B$6) | L51: =SUMIFS(CostLines!$L$2:$L$1055,CostLines!$A$2:$A$1055,$A51,CostLines!$P$2:$P$1055,1) | M51: =SUMIFS(CostLines!$L$2:$L$1055,CostLines!$A$2:$A$1055,$A51) | N51: =COUNTIFS(CostLines!$A$2:$A$1055,$A51)
A52: TN58BM3636 | B52: SOCKS | C52: =SUMIFS(CostLines!$L$2:$L$1055,CostLines!$A$2:$A$1055,$A52,CostLines!$C$2:$C$1055,C$1,CostLines!$I$2:$I$1055,README!$B$6) | D52: =SUMIFS(CostLines!$L$2:$L$1055,CostLines!$A$2:$A$1055,$A52,CostLines!$C$2:$C$1055,D$1,CostLines!$I$2:$I$1055,README!$B$6) | E52: =SUMIFS(CostLines!$L$2:$L$1055,CostLines!$A$2:$A$1055,$A52,CostLines!$C$2:$C$1055,E$1,CostLines!$I$2:$I$1055,README!$B$6) | F52: =SUMIFS(CostLines!$L$2:$L$1055,CostLines!$A$2:$A$1055,$A52,CostLines!$C$2:$C$1055,F$1,CostLines!$I$2:$I$1055,README!$B$6) | G52: =SUMIFS(CostLines!$L$2:$L$1055,CostLines!$A$2:$A$1055,$A52,CostLines!$C$2:$C$1055,G$1,CostLines!$I$2:$I$1055,README!$B$6) | H52: =SUMIFS(CostLines!$L$2:$L$1055,CostLines!$A$2:$A$1055,$A52,CostLines!$C$2:$C$1055,H$1,CostLines!$I$2:$I$1055,README!$B$6) | I52: =SUMIFS(CostLines!$L$2:$L$1055,CostLines!$A$2:$A$1055,$A52,CostLines!$C$2:$C$1055,I$1,CostLines!$I$2:$I$1055,README!$B$6) | J52: =SUM(C52:I52) | K52: =COUNTIFS(CostLines!$A$2:$A$1055,$A52,CostLines!$I$2:$I$1055,README!$B$6) | L52: =SUMIFS(CostLines!$L$2:$L$1055,CostLines!$A$2:$A$1055,$A52,CostLines!$P$2:$P$1055,1) | M52: =SUMIFS(CostLines!$L$2:$L$1055,CostLines!$A$2:$A$1055,$A52) | N52: =COUNTIFS(CostLines!$A$2:$A$1055,$A52)
A53: TN58BP3434 | B53: WOVEN | C53: =SUMIFS(CostLines!$L$2:$L$1055,CostLines!$A$2:$A$1055,$A53,CostLines!$C$2:$C$1055,C$1,CostLines!$I$2:$I$1055,README!$B$6) | D53: =SUMIFS(CostLines!$L$2:$L$1055,CostLines!$A$2:$A$1055,$A53,CostLines!$C$2:$C$1055,D$1,CostLines!$I$2:$I$1055,README!$B$6) | E53: =SUMIFS(CostLines!$L$2:$L$1055,CostLines!$A$2:$A$1055,$A53,CostLines!$C$2:$C$1055,E$1,CostLines!$I$2:$I$1055,README!$B$6) | F53: =SUMIFS(CostLines!$L$2:$L$1055,CostLines!$A$2:$A$1055,$A53,CostLines!$C$2:$C$1055,F$1,CostLines!$I$2:$I$1055,README!$B$6) | G53: =SUMIFS(CostLines!$L$2:$L$1055,CostLines!$A$2:$A$1055,$A53,CostLines!$C$2:$C$1055,G$1,CostLines!$I$2:$I$1055,README!$B$6) | H53: =SUMIFS(CostLines!$L$2:$L$1055,CostLines!$A$2:$A$1055,$A53,CostLines!$C$2:$C$1055,H$1,CostLines!$I$2:$I$1055,README!$B$6) | I53: =SUMIFS(CostLines!$L$2:$L$1055,CostLines!$A$2:$A$1055,$A53,CostLines!$C$2:$C$1055,I$1,CostLines!$I$2:$I$1055,README!$B$6) | J53: =SUM(C53:I53) | K53: =COUNTIFS(CostLines!$A$2:$A$1055,$A53,CostLines!$I$2:$I$1055,README!$B$6) | L53: =SUMIFS(CostLines!$L$2:$L$1055,CostLines!$A$2:$A$1055,$A53,CostLines!$P$2:$P$1055,1) | M53: =SUMIFS(CostLines!$L$2:$L$1055,CostLines!$A$2:$A$1055,$A53) | N53: =COUNTIFS(CostLines!$A$2:$A$1055,$A53)
